ERROR    [2018-08-24 05:48:41,206]  Internal Server Error: /projects/new/
Traceback (most recent call last):
  File "/home/snitch/PycharmProjects/VersionTwo/venv/lib/python3.5/site-packages/django/core/handlers/exception.py", line 35, in inner
    response = get_response(request)
  File "/home/snitch/PycharmProjects/VersionTwo/venv/lib/python3.5/site-packages/django/core/handlers/base.py", line 128, in _get_response
    response = self.process_exception_by_middleware(e, request)
  File "/home/snitch/PycharmProjects/VersionTwo/venv/lib/python3.5/site-packages/django/core/handlers/base.py", line 126, in _get_response
    response = wrapped_callback(request, *callback_args, **callback_kwargs)
  File "/home/snitch/PycharmProjects/VersionTwo/venv/lib/python3.5/site-packages/django/views/generic/base.py", line 69, in view
    return self.dispatch(request, *args, **kwargs)
  File "/home/snitch/PycharmProjects/VersionTwo/venv/lib/python3.5/site-packages/django/views/generic/base.py", line 89, in dispatch
    return handler(request, *args, **kwargs)
  File "/home/snitch/PycharmProjects/VersionTwo/tracker/views.py", line 59, in post
    ProjectController.create(username, password, name, description)
  File "/home/snitch/PycharmProjects/VersionTwo/venv/lib/python3.5/site-packages/takinata_lib-0.1-py3.5.egg/lib/controllers/project.py", line 37, in create
    log.info("Project {} was successfully created.".format(name))
NameError: name 'log' is not defined
INFO     [2018-08-24 05:52:25,103]  Project жопа was successfully created.
